Workbook
Name CLIENT: REF!$A:$A
Name NIVEAU: REF!$B:$B
Name parent: #REF!
Name TUTEUR: #REF!

Sheet ETAT 20262027
B1: INFOS | C1: E-MAIL | D1: NEM | E1: TUTEUR | F1: NOM | G1: niveau | H1: CLASSE | I1: OPTION | J1: REMISE | K1: JUSTIFICATION | L1: DEVIS ANNUEL | M1: REMBOURCEMENT | N1: DETTES | O1: REGLEMENTS DETTES | P1: TOTAL VERSEMENTS | Q1: TOTAL*CREANCE | R1: FI | S1: V2 | T1: 2V | U1: v3 | V1: DISTINATION | W1: 1T | X1: T2 | Y1: t3 | Z1: PSY1 | AA1: PSY2 | AB1: ORTH1 | AC1: ORTH2 | AD1: E-PLANT | AE1: Ratrapage | AF1: SEPTEMBRE | AG1: CREANCES SEPTEMBRE | AH1: DECEMBRE | AI1: CREANCES DECEMBRE | AJ1: MARS | AK1: CREANCES MARS | AL1: TOTAL | AN1: #REF!
D2: 0663701834/0660800317 | F2: ZIREG LEA | G2: PRIM | H2: CE1 | J2: 25500 | L2: =25000+205000+35000-J2 -> 239500 | P2: =R2+S2+T2+U2+W2+X2+Y2 -> 239500 | Q2: =L2-P2 -> 0 | R2: 25000 | S2: 71500 | T2: 71500 | U2: 71500
D3: 799534750/558498673 | F3: MERABTI RIHAM | G3: PRIM | H3: CE1 | I3: TRNSP | J3: 25500 | L3: =25000+205000+35000+55000-J3 -> 294500 | P3: =R3+S3+T3+U3+W3+X3+Y3 -> 294500 | Q3: =L3-P3 -> 0 | R3: 25000 | S3: 71500 | T3: 71500 | U3: 71500 | V3: DJENAT | W3: 30000 | X3: 15000 | Y3: 10000
D4: 770264718 | F4: BOUAICHA ACIL | G4: PRIM | H4: CE1 | J4: 5000 | L4: =25000+205000+35000-J4 -> 260000 | P4: =R4+S4+T4+U4+W4+X4+Y4 -> 117000 | Q4: =L4-P4 -> 143000 | R4: 25000 | S4: =82000+10000 -> 92000
D5: 795144767 | F5: SEDIKI ISHAK | G5: COLG | H5: 1AAM | I5: TRNSP | J5: =5000+10000+10000 -> 25000 | L5: =25000+305000+52000 -> 382000 | P5: =R5+S5+T5+U5+W5+X5+Y5 -> 152000 | Q5: =L5-P5 -> 230000 | R5: 25000 | S5: =122000-25000 -> 97000 | V5: BOUDOUAOU | W5: 30000
D6: 795144767 | F6: SEDIKI YAKOUB | G6: PRIM | H6: CE1 | I6: TRNSP | J6: 10000 | L6: =25000+205000+35000+52000 -> 317000 | P6: =R6+S6+T6+U6+W6+X6+Y6 -> 142000 | Q6: =L6-P6 -> 175000 | R6: 25000 | S6: 87000 | V6: BOUDOUAOU | W6: 30000
D7: 794811578 | F7: ZERGANI MAHDI | G7: PRIM | H7: CM2 | I7: TRNSP | J7: =20000+25000 -> 45000 | L7: =30000+250000+20000+52000-J7+1000 -> 308000 | P7: =R7+S7+T7+U7+W7+X7+Y7 -> 308000 | Q7: =L7-P7 -> 0 | R7: 30000 | S7: 28000 | T7: 100000 | U7: 98000 | V7: BOUDOUAOU | W7: 30000 | X7: 12000 | Y7: 10000
D8: 794811578 | F8: ZERGANI CHOAIB | G8: COLG | H8: 3AAM | I8: TRNSP | J8: =13000+5000+33000 -> 51000 | L8: =25000+330000+52000-J8 -> 356000 | P8: =R8+S8+T8+U8+W8+X8+Y8 -> 356000 | Q8: =L8-P8 -> 0 | R8: 25000 | S8: 100000 | T8: 100000 | U8: 79000 | V8: BOUDOUAOU | W8: 30000 | X8: 12000 | Y8: 10000
D9: 794811578 | F9: ZERGANI YAHIA | G9: COLG | H9: 3AAM | I9: TRNSP | J9: =13000+5000+33000 -> 51000 | L9: =25000+330000+52000-J9 -> 356000 | P9: =R9+S9+T9+U9+W9+X9+Y9 -> 356000 | Q9: =L9-P9 -> 0 | R9: 25000 | S9: 100000 | T9: 100000 | U9: =79000 -> 79000 | V9: BOUDOUAOU | W9: 30000 | X9: 12000 | Y9: 10000
D10: 660811501/553141609 | F10: YOUCEFI NAZIM | G10: COLG | H10: 3AAM | J10: =46000+16500 -> 62500 | L10: =25000+330000-J10 -> 292500 | P10: =R10+S10+T10+U10+W10+X10+Y10 -> 292500 | Q10: =L10-P10 -> 0 | R10: 25000 | S10: 69500 | T10: 99000 | U10: 99000
D11: 796945858 | F11: KHALDOUN HACENE | G11: PRIM | H11: CE2 | J11: =13000+22000+5000 -> 40000 | L11: =25000+35000+220000-J11 -> 240000 | P11: =R11+S11+T11+U11+W11+X11+Y11 -> 240000 | Q11: =L11-P11 -> 0 | R11: 25000 | S11: 63000 | T11: 76000 | U11: 76000
D12: 796945858 | F12: KHALDOUNE NOUR | G12: PRIM | H12: 4AP | J12: =18000+23000+5000 -> 46000 | L12: =25000+230000-J12 -> 209000 | P12: =R12+S12+T12+U12+W12+X12+Y12 -> 209000 | Q12: =L12-P12 -> 0 | R12: 25000 | S12: 46000 | T12: 69000 | U12: 69000
D13: 661308311 | F13: SEDIKI NASSIM | G13: PRIM | H13: CM1 | J13: =5000+18000 -> 23000 | L13: =25000+230000+35000-J13 -> 267000 | P13: =R13+S13+T13+U13+W13+X13+Y13 -> 109000 | Q13: =L13-P13 -> 158000 | R13: 25000 | S13: 84000
D14: 661308311 | E14: NV | F14: SEDIKI YACINE | G14: GS | H14: GS | J14: 5000 | L14: =180000+165000-J14 -> 340000 | P14: =R14+S14+T14+U14+W14+X14+Y14 -> 79000 | Q14: =L14-P14 -> 261000 | R14: 18000 | S14: =66000-5000 -> 61000
D15: 561343761 | F15: HAMADACHE AHMED | G15: PRIM | H15: CM2 | I15: TRNSP | J15: 40000 | L15: =30000+250000+20000+43000-J15 -> 303000 | P15: =R15+S15+T15+U15+W15+X15+Y15 -> 303000 | Q15: =L15-P15 -> 0 | R15: 30000 | S15: 70000 | T15: 80000 | U15: 80000 | V15: FIGUIER | W15: 20000 | X15: 13000 | Y15: 10000
D16: 661652830 | F16: ALLOUCHE CHAIMA | G16: LYC | H16: 3EM | L16: 396000 | P16: =R16+S16+T16+U16+W16+X16+Y16 -> 30000 | Q16: =L16-P16 -> 366000 | R16: 30000
D17: 796519468 | F17: GASSMI YOUNES | G17: COLG | H17: 3AAM | J17: 34500 | L17: 320500 | P17: =R17+S17+T17+U17+W17+X17+Y17 -> 122500 | Q17: =L17-P17 -> 198000 | R17: 25000 | S17: 97500
D18: 796519468 | F18: GASSMI YASSINE | G18: COLG | H18: 4AAM | J18: 42000 | L18: 328000 | P18: =R18+S18+T18+U18+W18+X18+Y18 -> 127500 | Q18: =L18-P18 -> 200500 | R18: 30000 | S18: 97500
D19: 792775082 | F19: ABDENOUS ABDERHMAN | G19: LYC | H19: 3EM | J19: =10000+5000 -> 15000 | L19: =30000+356000-J19 -> 371000 | P19: =R19+S19+T19+U19+W19+X19+Y19 -> 161000 | Q19: =L19-P19 -> 210000 | R19: 30000 | S19: =146000-15000 -> 131000
D20: 792775082 | F20: ABDENOUS ACIL | G20: PRIM | H20: CM2 | J20: 20000 | L20: =30000+250000+20000-J20 -> 280000 | P20: =R20+S20+T20+U20+W20+X20+Y20 -> 120000 | Q20: =L20-P20 -> 160000 | R20: 30000 | S20: =70000+20000 -> 90000
D21: 672208803 | E21: NV | F21: SITOUAH ALAAEDINE YOUCEF | G21: PRIM | H21: CP | L21: =25000+185000+35000-J21 -> 245000 | P21: =R21+S21+T21+U21+W21+X21+Y21 -> 114000 | Q21: =L21-P21 -> 131000 | R21: 25000 | S21: =74000+15000 -> 89000
D22: 776590820 | F22: BENYOUCEF ANAIS | G22: PRIM | H22: CM2 | J22: =25000+15000 -> 40000 | L22: =30000+250000+20000-J22 -> 260000 | P22: =R22+S22+T22+U22+W22+X22+Y22 -> 260000 | Q22: =L22-P22 -> 0 | R22: 30000 | S22: 70000 | T22: 80000 | U22: 80000
D23: 556517114/661810321 | F23: LAMARA MED SARA | G23: COLG | H23: 4AAM | J23: =20000 -> 20000 | L23: =30000+340000-J23 -> 350000 | P23: =R23+S23+T23+U23+W23+X23+Y23 -> 146000 | Q23: =L23-P23 -> 204000 | R23: 30000 | S23: 116000
D24: 698868963 | F24: RABIA HACEN | G24: COLG | H24: 3AAM | J24: =33000+13000 -> 46000 | L24: =25000+330000-J24 -> 309000 | P24: =R24+S24+T24+U24+W24+X24+Y24 -> 309000 | Q24: =L24-P24 -> 0 | R24: 25000 | S24: 86000 | T24: 99000 | U24: 99000
D25: 560245811 | F25: MENSOUR DOUHA | G25: PRIM | H25: CM2 | I25: TRNSP | L25: =30000+250000+20000+55000-J25 -> 355000 | P25: =R25+S25+T25+U25+W25+X25+Y25 -> 30000 | Q25: =L25-P25 -> 325000 | R25: 30000 | V25: KHEMIS KHECHNA
D26: 791948957/655583839 | F26: HAMIDOUCH YANIS | G26: LYC | H26: 2EM | J26: 13000 | L26: =25000+355000-J26 -> 367000 | P26: =R26+S26+T26+U26+W26+X26+Y26 -> 154000 | Q26: =L26-P26 -> 213000 | R26: 25000 | S26: =142000-13000 -> 129000
D27: 550265831 | F27: TAKOUCHET ROUAIA | G27: COLG | H27: 4AAM | J27: 54000 | L27: =30000+340000+55000-J27 -> 371000 | P27: =R27+S27+T27+U27+W27+X27+Y27 -> 371000 | Q27: =L27-P27 -> 0 | R27: 30000 | S27: 82000 | T27: 102000 | U27: 102000 | V27: BORDJMNAIL | W27: 30000 | X27: 15000 | Y27: 10000
D28: 699718098 | F28: BERAHIMI RACIM | G28: PRIM | H28: CM1 | J28: 30000 | L28: =25000+35000+230000-J28 -> 260000 | P28: =R28+S28+T28+U28+W28+X28+Y28 -> 106000 | Q28: =L28-P28 -> 154000 | R28: 25000 | S28: 77000 | T28: 4000
D29: 699718098 | F29: BERAHIMI RIMES | G29: COLG | H29: 2AAM | J29: 39000 | L29: =25000+320000-J29 -> 306000 | P29: =R29+S29+T29+U29+W29+X29+Y29 -> 114000 | Q29: =L29-P29 -> 192000 | R29: 25000 | S29: 89000
D30: 562873864 | F30: REZIG WALID | G30: PRIM | H30: 3AP | I30: TRNSP | J30: 22000 | L30: =25000+220000+52000-J30 -> 275000 | P30: =R30+S30+T30+U30+W30+X30+Y30 -> 130000 | Q30: =L30-P30 -> 145000 | R30: 25000 | S30: 75000 | V30: THENIA | W30: 30000
D31: 661742904 | F31: TAMERYOULT MALAK | G31: LYC | H31: 2EM | J31: 13000 | L31: =25000+355000-J31 -> 367000 | P31: =R31+S31+T31+U31+W31+X31+Y31 -> 154000 | Q31: =L31-P31 -> 213000 | R31: 25000 | S31: 129000
D32: 55021780/0699648046 | F32: KESASI ELYAS | G32: COLG | H32: 3AAM | J32: =33000+13000+5000 -> 51000 | L32: =25000+330000-J32 -> 304000 | P32: =R32+S32+T32+U32+W32+X32+Y32 -> 304000 | Q32: =L32-P32 -> 0 | R32: 25000 | S32: 81000 | T32: 99000 | U32: 99000
D33: 561678897/562537254 | F33: ATTOUCHE MASSIL | G33: AUTISTE | H33: AUTISTE | J33: 30000 | L33: =23000+250000+40000-J33 -> 283000 | P33: =R33+S33+T33+U33+W33+X33+Y33 -> 113000 | Q33: =L33-P33 -> 170000 | R33: 23000 | S33: 90000
D34: 559744831 | E34: NV | F34: ABDI DANIA | G34: GS | H34: GS | J34: 5000 | L34: =18000+135000-J34 -> 148000 | P34: =R34+S34+T34+U34+W34+X34+Y34 -> 18000 | Q34: =L34-P34 -> 130000 | R34: 18000
D35: 555647502 | F35: LOUANCHI RITADJE | G35: PRIM | H35: CM2 | J35: 20000 | L35: =30000+20000+250000-J35 -> 280000 | P35: =R35+S35+T35+U35+W35+X35+Y35 -> 127000 | Q35: =L35-P35 -> 153000 | R35: 25000 | S35: =122000-20000 -> 102000
D36: 555647502 | F36: LOUANCHI MERIEME | G36: COLG | H36: 1AAM | J36: 25000 | L36: =25000+305000-J36 -> 305000 | P36: =R36+S36+T36+U36+W36+X36+Y36 -> 115000 | Q36: =L36-P36 -> 190000 | R36: 30000 | S36: =110000-25000 -> 85000
D37: 699015001 | F37: BENZAOUI KHADIJA | G37: LYC | H37: 1ER | J37: =50000+14500 -> 64500 | L37: =25000+350000-J37 -> 310500 | P37: =R37+S37+T37+U37+W37+X37+Y37 -> 310500 | Q37: =L37-P37 -> 0 | R37: 25000 | S37: 75500 | T37: 105000 | U37: 105000
D38: 699015001 | F38: BENZAOUIMED TAHA | G38: COLG | H38: 4AAM | J38: 50000 | L38: =30000+340000-J38 -> 320000 | P38: =R38+S38+T38+U38+W38+X38+Y38 -> 320000 | Q38: =L38-P38 -> 0 | R38: 25000 | S38: 91000 | T38: 102000 | U38: 102000
D39: 699015001 | F39: BENZAOUI FATIMA | G39: COLG | H39: 1AAM | J39: 50000 | L39: =25000+305000-J39 -> 280000 | P39: =R39+S39+T39+U39+W39+X39+Y39 -> 280000 | Q39: =L39-P39 -> 0 | R39: 25000 | S39: 72000 | T39: 91500 | U39: 91500
D40: 699015001 | F40: BENZAOUI AHMED YACINE | G40: GS | H40: GS | J40: 50000 | L40: =18000+165000-J40 -> 133000 | P40: =R40+S40+T40+U40+W40+X40+Y40 -> 133000 | Q40: =L40-P40 -> 0 | R40: 18000 | S40: 16000 | T40: 49500 | U40: 49500
...

Sheet BON 
A4: Situation Client 2021-2022
A7: Etat des versements
E8: CLIENT | F8: ABDELAOUI | H8: DATE | I8: =TODAY() -> 46227
A10: DEVIS ANNUEL | C10: =+VLOOKUP(F8,'PAR PARENT'!A4:E785,2,0) -> #REF! | E10: ELEVES | G10: DEVIS | H10: TOTAL VERSE | I10: RESTE VERSE
E12: ABDELAOUI INES | H12: =+VLOOKUP(E12,'PAR PARENT'!A4:E785,3,0) -> #REF! | I12: =+VLOOKUP(E12,'PAR PARENT'!A4:K786,6,0) -> #REF!
A13: INSCRIPTION | E13: ABDELAOUI SAMY | H13: =+VLOOKUP(E13,'PAR PARENT'!A5:E786,3,0) -> #REF! | I13: =+VLOOKUP(E13,'PAR PARENT'!A5:K787,6,0) -> #REF!
A15: 2EME TRANCHE
A17: 3ème TRANCHE
A19: 4ème TRANCHE
A20: Historique Reglements
A22: =+VLOOKUP(F8,'Etat General Versement'!G7:AS1255,33,0) -> #REF!
A23: =+VLOOKUP(F8,'Etat General Versement'!G7:AS1255,34,0) -> #REF!
A24: =+VLOOKUP(F8,'Etat General Versement'!G7:AS1255,35,0) -> #REF!
A25: =+VLOOKUP(F8,'Etat General Versement'!G7:AS1255,36,0) -> #REF!
A26: =+VLOOKUP(F8,'Etat General Versement'!G7:AS1255,37,0) -> #REF!
A27: =+VLOOKUP(F8,'Etat General Versement'!G7:AS1255,38,0) -> #REF!
A28: =+VLOOKUP(F8,'Etat General Versement'!G7:AS1255,39,0) -> #REF!
A29: =+VLOOKUP(F8,'Etat General Versement'!G7:AS1255,40,0) -> #REF!
A30: =+VLOOKUP(F8,'Etat General Versement'!G7:AS1255,41,0) -> #REF!
A31: =+VLOOKUP(F8,'Etat General Versement'!G7:AS1255,42,0) -> #REF!

Sheet Devis
A2: Client | B2: MAHAMED OUSSAID
F6: Devis
F7: Devis n° | I7: 0101/2021/2022
F9: Date | I9: =TODAY() -> 46227
F11: Validité
A13: Prenom élève | D13: Classe | E13: F I | F13: Frais Scolarisation | G13: Services | I13: Total
A15: MAHDI | D15: CM1 | E15: 28000 | F15: 210000 | G15: Transport | H15: 43000 | I15: =+SUM(A15:H15) -> 281000
A16: AMINE | E16: 18000 | F16: 125000 | G16: Transport | H16: 43000 | I16: =+SUM(A16:H16) -> 186000
D17: GS | E17: 18000 | F17: 125000 | G17: Transport | H17: 43000 | I17: =+SUM(A17:H17) -> 186000
G27: Sous-total | I27: =+SUM(I15:I26) -> 653000
G29: Réduction | I29: 10000
G31: Montant Total DZD | I31: =+I27-I29 -> 643000
A35: Nb 01: une remise de 5% sois | D35: =+SUM(F15:F26)*0.05 -> 23000 | E35: est rajoutée si le paiement est effectué en totalité avant le 30 juin 2021
A37: Nb 02: Toute inscription doit etre confirmée par un versement ( frais d'inscription + 1er tranche)
E39: =18000*2+28000+21000+25000 -> 110000
A41: Note
A42: Paiement par chèque,bien notifié l'ordre "Sarl Elimtiyaz"
A43: Versement ou du virement bancaire nous renvoyer par mail une copie du bordereau de versement
A44: RIB:00400141400004179159
A50: Client | B50: KOUBA
F54: Devis
F55: Devis n° | I55: 0102/2021/2022
F57: Date | I57: =TODAY() -> 46227
F59: Validité | I59: 44362
A61: Prenom élève | D61: Classe | E61: F I | F61: Frais Scolarisation | G61: Services | I61: Total
A63: CHOUROUK | D63: 2AM | E63: 28000 | F63: 250000 | I63: =+SUM(A63:H63) -> 278000
A64: HALA | D64: 4AP | E64: 28000 | F64: 180000 | I64: =+SUM(A64:H64) -> 208000
A65: AHLAM | D65: CP | E65: 28000 | F65: 170000 | I65: =+SUM(A65:H65) -> 198000
G75: Sous-total | I75: =+SUM(I63:I74) -> 684000
G77: Réduction | I77: 41500
G79: Montant Total DZD | I79: =+I75-I77 -> 642500
A83: Nb 01: une remise de 5% sois | D83: =+SUM(F63:F74)*0.05 -> 30000 | E83: est rajoutée si le paiement est effectué en totalité avant le 30 juin 2021
A85: Nb 02: Toute inscription doit etre confirmée par un versement ( frais d'inscription + 1er tranche)
E87: =28000*3+72000+100000+68000-41500 -> 282500
A89: Note
A90: Paiement par chèque,bien notifié l'ordre "Sarl Elimtiyaz"
A91: Versement ou du virement bancaire nous renvoyer par mail une copie du bordereau de versement
A92: RIB:00400141400004179159
A98: Client | B98: DJAOUD
F102: Devis
...

Sheet REF
A1: MERDAS SAMIR | B1: MS | D1: BOUMERDES
A2: TALAOOURAR YOUNES | B2: GS | D2: CORSO
A3: BELRECHID | B3: 1AP | D3: SAHEL
A4: HARBI | B4: CP | D4: FIGUIER
A5: MOULFI | B5: 2AP | D5: ZEMOURI
A6: HAMADACHE | B6: CE1 | D6: BOUDOUAOU
A7: HASSAIN | B7: 3AP | D7: REGHIAA
A8: SLIMANI | B8: CE2 | D8: ROUIBA
B9: 4AP | D9: BORDJ MNAIL
B10: CM1 | D10: SI MUSTAPHA
B11: 5AP | D11: ISSER
B12: CM2 | D12: THENIA
B13: 1AAM | D13: BENI AMRANE
B14: 2AAM | D14: OULED MOUSSA
B15: 3AAM | D15: OULED HEDDAJ /HOUCHE MEKHEFI
B16: 4AAM | D16: KHEMIS KHENCHELA
B17: 1AS | D17: TIDJELABINE
B18: 2AS | D18: BENYOUNES
B19: 3AS | D19: SOUK ELHAD
B20: 1cs | D20: CAP DJENET
B21: 2cs
B22: 3cs
B23: 4cs
B24: autiste
B25: PS
B26: TPS
